[2023-03-29 15:30:51,959] {taskinstance.py:1159} INFO - Dependencies all met for <TaskInstance: data_merge_dag.merge_task manual__2023-03-29T15:25:48.046424+00:00 [queued]>
[2023-03-29 15:30:51,971] {taskinstance.py:1159} INFO - Dependencies all met for <TaskInstance: data_merge_dag.merge_task manual__2023-03-29T15:25:48.046424+00:00 [queued]>
[2023-03-29 15:30:51,971] {taskinstance.py:1356} INFO - 
--------------------------------------------------------------------------------
[2023-03-29 15:30:51,972] {taskinstance.py:1357} INFO - Starting attempt 2 of 4
[2023-03-29 15:30:51,972] {taskinstance.py:1358} INFO - 
--------------------------------------------------------------------------------
[2023-03-29 15:30:51,986] {taskinstance.py:1377} INFO - Executing <Task(PythonOperator): merge_task> on 2023-03-29 15:25:48.046424+00:00
[2023-03-29 15:30:51,991] {standard_task_runner.py:52} INFO - Started process 74 to run task
[2023-03-29 15:30:51,993] {standard_task_runner.py:79} INFO - Running: ['***', 'tasks', 'run', 'data_merge_dag', 'merge_task', 'manual__2023-03-29T15:25:48.046424+00:00', '--job-id', '452', '--raw', '--subdir', 'DAGS_FOLDER/data_merge.py', '--cfg-path', '/tmp/tmpmexcn8g2', '--error-file', '/tmp/tmp93zrsjft']
[2023-03-29 15:30:51,993] {standard_task_runner.py:80} INFO - Job 452: Subtask merge_task
[2023-03-29 15:30:52,050] {task_command.py:369} INFO - Running <TaskInstance: data_merge_dag.merge_task manual__2023-03-29T15:25:48.046424+00:00 [running]> on host cbb3159fbb01
[2023-03-29 15:30:52,129] {taskinstance.py:1571} INFO - Exporting the following env vars:
AIRFLOW_CTX_DAG_OWNER=kartaca
AIRFLOW_CTX_DAG_ID=data_merge_dag
AIRFLOW_CTX_TASK_ID=merge_task
AIRFLOW_CTX_EXECUTION_DATE=2023-03-29T15:25:48.046424+00:00
AIRFLOW_CTX_TRY_NUMBER=2
AIRFLOW_CTX_DAG_RUN_ID=manual__2023-03-29T15:25:48.046424+00:00
[2023-03-29 15:30:52,134] {taskinstance.py:1889} ERROR - Task failed with exception
Traceback (most recent call last):
  File "/home/airflow/.local/lib/python3.7/site-packages/mysql/connector/connection_cext.py", line 538, in cmd_query
    query_attrs=self._query_attrs)
_mysql_connector.MySQLInterfaceError: You have an error in your SQL syntax; check the manual that corresponds to your MySQL server version for the right syntax to use near 'IF EXISTS data_merge' at line 1

During handling of the above exception, another exception occurred:

Traceback (most recent call last):
  File "/home/airflow/.local/lib/python3.7/site-packages/airflow/operators/python.py", line 171, in execute
    return_value = self.execute_callable()
  File "/home/airflow/.local/lib/python3.7/site-packages/airflow/operators/python.py", line 189, in execute_callable
    return self.python_callable(*self.op_args, **self.op_kwargs)
  File "/opt/airflow/dags/data_merge.py", line 33, in merge
    cursor.execute("DROP IF EXISTS data_merge")
  File "/home/airflow/.local/lib/python3.7/site-packages/mysql/connector/cursor_cext.py", line 271, in execute
    raw_as_string=self._raw_as_string)
  File "/home/airflow/.local/lib/python3.7/site-packages/mysql/connector/connection_cext.py", line 541, in cmd_query
    sqlstate=exc.sqlstate)
mysql.connector.errors.ProgrammingError: 1064 (42000): You have an error in your SQL syntax; check the manual that corresponds to your MySQL server version for the right syntax to use near 'IF EXISTS data_merge' at line 1
[2023-03-29 15:30:52,143] {taskinstance.py:1400} INFO - Marking task as UP_FOR_RETRY. dag_id=data_merge_dag, task_id=merge_task, execution_date=20230329T152548, start_date=20230329T153051, end_date=20230329T153052
[2023-03-29 15:30:52,157] {standard_task_runner.py:97} ERROR - Failed to execute job 452 for task merge_task (1064 (42000): You have an error in your SQL syntax; check the manual that corresponds to your MySQL server version for the right syntax to use near 'IF EXISTS data_merge' at line 1; 74)
[2023-03-29 15:30:52,166] {local_task_job.py:156} INFO - Task exited with return code 1
[2023-03-29 15:30:52,209] {local_task_job.py:273} INFO - 0 downstream tasks scheduled from follow-on schedule check
