[2023-03-28 22:48:19,690] {taskinstance.py:1159} INFO - Dependencies all met for <TaskInstance: country_dag.insert_task scheduled__2023-03-27T10:00:00+00:00 [queued]>
[2023-03-28 22:48:19,704] {taskinstance.py:1159} INFO - Dependencies all met for <TaskInstance: country_dag.insert_task scheduled__2023-03-27T10:00:00+00:00 [queued]>
[2023-03-28 22:48:19,705] {taskinstance.py:1356} INFO - 
--------------------------------------------------------------------------------
[2023-03-28 22:48:19,705] {taskinstance.py:1357} INFO - Starting attempt 1 of 4
[2023-03-28 22:48:19,705] {taskinstance.py:1358} INFO - 
--------------------------------------------------------------------------------
[2023-03-28 22:48:19,723] {taskinstance.py:1377} INFO - Executing <Task(PythonOperator): insert_task> on 2023-03-27 10:00:00+00:00
[2023-03-28 22:48:19,729] {standard_task_runner.py:52} INFO - Started process 78 to run task
[2023-03-28 22:48:19,733] {standard_task_runner.py:79} INFO - Running: ['***', 'tasks', 'run', 'country_dag', 'insert_task', 'scheduled__2023-03-27T10:00:00+00:00', '--job-id', '286', '--raw', '--subdir', 'DAGS_FOLDER/country_dag.py', '--cfg-path', '/tmp/tmpikzjs70w', '--error-file', '/tmp/tmp249vyht2']
[2023-03-28 22:48:19,734] {standard_task_runner.py:80} INFO - Job 286: Subtask insert_task
[2023-03-28 22:48:19,791] {task_command.py:369} INFO - Running <TaskInstance: country_dag.insert_task scheduled__2023-03-27T10:00:00+00:00 [running]> on host c0bc2ca16b74
[2023-03-28 22:48:19,856] {taskinstance.py:1571} INFO - Exporting the following env vars:
AIRFLOW_CTX_DAG_OWNER=Ranga
AIRFLOW_CTX_DAG_ID=country_dag
AIRFLOW_CTX_TASK_ID=insert_task
AIRFLOW_CTX_EXECUTION_DATE=2023-03-27T10:00:00+00:00
AIRFLOW_CTX_TRY_NUMBER=1
AIRFLOW_CTX_DAG_RUN_ID=scheduled__2023-03-27T10:00:00+00:00
[2023-03-28 22:48:19,868] {taskinstance.py:1889} ERROR - Task failed with exception
Traceback (most recent call last):
  File "/home/airflow/.local/lib/python3.7/site-packages/airflow/operators/python.py", line 171, in execute
    return_value = self.execute_callable()
  File "/home/airflow/.local/lib/python3.7/site-packages/airflow/operators/python.py", line 189, in execute_callable
    return self.python_callable(*self.op_args, **self.op_kwargs)
  File "/opt/airflow/dags/country_dag.py", line 44, in insert
    logging.info(key)
NameError: name 'logging' is not defined
[2023-03-28 22:48:19,880] {taskinstance.py:1400} INFO - Marking task as UP_FOR_RETRY. dag_id=country_dag, task_id=insert_task, execution_date=20230327T100000, start_date=20230328T224819, end_date=20230328T224819
[2023-03-28 22:48:19,893] {standard_task_runner.py:97} ERROR - Failed to execute job 286 for task insert_task (name 'logging' is not defined; 78)
[2023-03-28 22:48:19,907] {local_task_job.py:156} INFO - Task exited with return code 1
[2023-03-28 22:48:19,944] {local_task_job.py:273} INFO - 0 downstream tasks scheduled from follow-on schedule check
