[2023-03-29 19:30:26,642] {taskinstance.py:1159} INFO - Dependencies all met for <TaskInstance: data_merge_dag.merge_task scheduled__2023-03-29T10:05:00+00:00 [queued]>
[2023-03-29 19:30:26,668] {taskinstance.py:1159} INFO - Dependencies all met for <TaskInstance: data_merge_dag.merge_task scheduled__2023-03-29T10:05:00+00:00 [queued]>
[2023-03-29 19:30:26,668] {taskinstance.py:1356} INFO - 
--------------------------------------------------------------------------------
[2023-03-29 19:30:26,668] {taskinstance.py:1357} INFO - Starting attempt 2 of 4
[2023-03-29 19:30:26,668] {taskinstance.py:1358} INFO - 
--------------------------------------------------------------------------------
[2023-03-29 19:30:26,703] {taskinstance.py:1377} INFO - Executing <Task(PythonOperator): merge_task> on 2023-03-29 10:05:00+00:00
[2023-03-29 19:30:26,715] {standard_task_runner.py:52} INFO - Started process 78 to run task
[2023-03-29 19:30:26,734] {standard_task_runner.py:79} INFO - Running: ['***', 'tasks', 'run', 'data_merge_dag', 'merge_task', 'scheduled__2023-03-29T10:05:00+00:00', '--job-id', '663', '--raw', '--subdir', 'DAGS_FOLDER/data_merge.py', '--cfg-path', '/tmp/tmp80brroqy', '--error-file', '/tmp/tmpxnbe78xg']
[2023-03-29 19:30:26,735] {standard_task_runner.py:80} INFO - Job 663: Subtask merge_task
[2023-03-29 19:30:26,927] {task_command.py:369} INFO - Running <TaskInstance: data_merge_dag.merge_task scheduled__2023-03-29T10:05:00+00:00 [running]> on host 491e5e6b4ad4
[2023-03-29 19:30:27,086] {taskinstance.py:1571} INFO - Exporting the following env vars:
AIRFLOW_CTX_DAG_OWNER=kartaca
AIRFLOW_CTX_DAG_ID=data_merge_dag
AIRFLOW_CTX_TASK_ID=merge_task
AIRFLOW_CTX_EXECUTION_DATE=2023-03-29T10:05:00+00:00
AIRFLOW_CTX_TRY_NUMBER=2
AIRFLOW_CTX_DAG_RUN_ID=scheduled__2023-03-29T10:05:00+00:00
[2023-03-29 19:30:27,254] {taskinstance.py:1889} ERROR - Task failed with exception
Traceback (most recent call last):
  File "/home/airflow/.local/lib/python3.7/site-packages/mysql/connector/connection_cext.py", line 538, in cmd_query
    query_attrs=self._query_attrs)
_mysql_connector.MySQLInterfaceError: Table 'data_merge' already exists

During handling of the above exception, another exception occurred:

Traceback (most recent call last):
  File "/home/airflow/.local/lib/python3.7/site-packages/airflow/operators/python.py", line 171, in execute
    return_value = self.execute_callable()
  File "/home/airflow/.local/lib/python3.7/site-packages/airflow/operators/python.py", line 189, in execute_callable
    return self.python_callable(*self.op_args, **self.op_kwargs)
  File "/opt/airflow/dags/data_merge.py", line 35, in merge
    cursor.execute("CREATE TABLE data_merge AS SELECT country.country_abbr , currency.currency_type , country.country_name FROM country JOIN currency ON country.country_abbr =currency.country_abbr ;")
  File "/home/airflow/.local/lib/python3.7/site-packages/mysql/connector/cursor_cext.py", line 271, in execute
    raw_as_string=self._raw_as_string)
  File "/home/airflow/.local/lib/python3.7/site-packages/mysql/connector/connection_cext.py", line 541, in cmd_query
    sqlstate=exc.sqlstate)
mysql.connector.errors.ProgrammingError: 1050 (42S01): Table 'data_merge' already exists
[2023-03-29 19:30:27,278] {taskinstance.py:1400} INFO - Marking task as UP_FOR_RETRY. dag_id=data_merge_dag, task_id=merge_task, execution_date=20230329T100500, start_date=20230329T193026, end_date=20230329T193027
[2023-03-29 19:30:27,305] {standard_task_runner.py:97} ERROR - Failed to execute job 663 for task merge_task (1050 (42S01): Table 'data_merge' already exists; 78)
[2023-03-29 19:30:27,348] {local_task_job.py:156} INFO - Task exited with return code 1
[2023-03-29 19:30:27,425] {local_task_job.py:273} INFO - 0 downstream tasks scheduled from follow-on schedule check
