[2023-03-29 15:07:25,637] {taskinstance.py:1159} INFO - Dependencies all met for <TaskInstance: currency_dag.insert_task manual__2023-03-29T15:07:22.291921+00:00 [queued]>
[2023-03-29 15:07:25,647] {taskinstance.py:1159} INFO - Dependencies all met for <TaskInstance: currency_dag.insert_task manual__2023-03-29T15:07:22.291921+00:00 [queued]>
[2023-03-29 15:07:25,647] {taskinstance.py:1356} INFO - 
--------------------------------------------------------------------------------
[2023-03-29 15:07:25,647] {taskinstance.py:1357} INFO - Starting attempt 1 of 4
[2023-03-29 15:07:25,647] {taskinstance.py:1358} INFO - 
--------------------------------------------------------------------------------
[2023-03-29 15:07:25,661] {taskinstance.py:1377} INFO - Executing <Task(PythonOperator): insert_task> on 2023-03-29 15:07:22.291921+00:00
[2023-03-29 15:07:25,665] {standard_task_runner.py:52} INFO - Started process 96 to run task
[2023-03-29 15:07:25,667] {standard_task_runner.py:79} INFO - Running: ['***', 'tasks', 'run', 'currency_dag', 'insert_task', 'manual__2023-03-29T15:07:22.291921+00:00', '--job-id', '351', '--raw', '--subdir', 'DAGS_FOLDER/currency_dag.py', '--cfg-path', '/tmp/tmpj5ltkvpy', '--error-file', '/tmp/tmpl01xbx9k']
[2023-03-29 15:07:25,667] {standard_task_runner.py:80} INFO - Job 351: Subtask insert_task
[2023-03-29 15:07:25,720] {task_command.py:369} INFO - Running <TaskInstance: currency_dag.insert_task manual__2023-03-29T15:07:22.291921+00:00 [running]> on host 288a39a1a75c
[2023-03-29 15:07:25,798] {taskinstance.py:1571} INFO - Exporting the following env vars:
AIRFLOW_CTX_DAG_OWNER=kartaca
AIRFLOW_CTX_DAG_ID=currency_dag
AIRFLOW_CTX_TASK_ID=insert_task
AIRFLOW_CTX_EXECUTION_DATE=2023-03-29T15:07:22.291921+00:00
AIRFLOW_CTX_TRY_NUMBER=1
AIRFLOW_CTX_DAG_RUN_ID=manual__2023-03-29T15:07:22.291921+00:00
[2023-03-29 15:07:25,810] {taskinstance.py:1889} ERROR - Task failed with exception
Traceback (most recent call last):
  File "/home/airflow/.local/lib/python3.7/site-packages/airflow/operators/python.py", line 171, in execute
    return_value = self.execute_callable()
  File "/home/airflow/.local/lib/python3.7/site-packages/airflow/operators/python.py", line 189, in execute_callable
    return self.python_callable(*self.op_args, **self.op_kwargs)
  File "/opt/airflow/dags/currency_dag.py", line 41, in insert
    for key in currency_response:
TypeError: 'NoneType' object is not iterable
[2023-03-29 15:07:25,817] {taskinstance.py:1400} INFO - Marking task as UP_FOR_RETRY. dag_id=currency_dag, task_id=insert_task, execution_date=20230329T150722, start_date=20230329T150725, end_date=20230329T150725
[2023-03-29 15:07:25,831] {standard_task_runner.py:97} ERROR - Failed to execute job 351 for task insert_task ('NoneType' object is not iterable; 96)
[2023-03-29 15:07:25,840] {local_task_job.py:156} INFO - Task exited with return code 1
[2023-03-29 15:07:25,878] {local_task_job.py:273} INFO - 0 downstream tasks scheduled from follow-on schedule check
